Workbook

Sheet Example 1
B1: Age
A2: Year | B2: 12 | C2: 24 | D2: 36 | E2: 48 | F2: 60 | G2: 72 | H2: 84 | I2: 96 | J2: 108 | K2: 120 | L2: 132 | M2: 144 | N2: 156 | O2: 168 | P2: 180 | Q2: 192 | R2: 204 | S2: 216 | T2: 228 | U2: 240 | V2: 252 | W2: 264 | X2: 276 | Y2: 288 | Z2: 300
A3: 2012
A4: 2013
A5: 2014
A6: 2015
A7: 2016
A8: 2017 | B8: 7719 | C8: 17079 | D8: 32138 | E8: 55930 | F8: 75400 | G8: 99711 | H8: 113647 | I8: 104617 | J8: 110040 | K8: 110973
A9: 2018 | B9: 6387 | C9: 17842 | D9: 35429 | E9: 57222 | F9: 80791 | G9: 95150 | H9: 120432 | I9: 112450 | J9: 145953
A10: 2019 | B10: 8347 | C10: 18022 | D10: 36758 | E10: 71537 | F10: 87621 | G10: 100813 | H10: 121789 | I10: 121255
A11: 2020 | B11: 7700 | C11: 21502 | D11: 43272 | E11: 64383 | F11: 78572 | G11: 93042 | H11: 134394
A12: 2021 | B12: 8223 | C12: 23181 | D12: 37376 | E12: 67965 | F12: 72611 | G12: 76059
A13: 2022 | B13: 12122 | C13: 26156 | D13: 48834 | E13: 82909 | F13: 94462
A14: 2023 | B14: 7596 | C14: 19404 | D14: 65507 | E14: 111264
A15: 2024 | B15: 10264 | C15: 44816 | D15: 62018
A16: 2025 | B16: 20162 | C16: 28107
A17: 2026 | B17: 10682
B19: 0 | C19: 1 | D19: 2 | E19: 3 | F19: 4 | G19: 5 | H19: 6 | I19: 7 | J19: 8 | K19: 9 | L19: 10 | M19: 11 | N19: 12 | O19: 13 | P19: 14 | Q19: 15
A20: age-to-age | B20: =SUM(OFFSET(C13:C17,-B19-1,0))/SUM(OFFSET(B13:B17,-B19-1,0)) -> 2.4271249 | C20: =SUM(OFFSET(D13:D17,-C19-1,0))/SUM(OFFSET(C13:C17,-C19-1,0)) -> 1.9029239 | D20: =SUM(OFFSET(E13:E17,-D19-1,0))/SUM(OFFSET(D13:D17,-D19-1,0)) -> 1.7176404 | E20: =SUM(OFFSET(F13:F17,-E19-1,0))/SUM(OFFSET(E13:E17,-E19-1,0)) -> 1.2035981 | F20: =SUM(OFFSET(G13:G17,-F19-1,0))/SUM(OFFSET(F13:F17,-F19-1,0)) -> 1.1766605 | G20: =SUM(OFFSET(H13:H17,-G19-1,0))/SUM(OFFSET(G13:G17,-G19-1,0)) -> 1.2612344 | H20: =SUM(OFFSET(I13:I17,-H19-1,0))/SUM(OFFSET(H13:H17,-H19-1,0)) -> 0.9506952 | I20: =SUM(OFFSET(J13:J17,-I19-1,0))/SUM(OFFSET(I13:I17,-I19-1,0)) -> 1.1793271 | J20: =SUM(OFFSET(K13:K17,-J19-1,0))/SUM(OFFSET(J13:J17,-J19-1,0)) -> 1.0084787 | K20: 1 | L20: 1 | M20: 1 | N20: 1 | O20: 1 | P20: 1
A21: age-to-ultimate | B21: =B20*C21 -> 16.021995 | C21: =C20*D21 -> 6.6012238 | D21: =D20*E21 -> 3.4689899 | E21: =E20*F21 -> 2.0196253 | F21: =F20*G21 -> 1.6779898 | G21: =G20*H21 -> 1.4260611 | H21: =H20*I21 -> 1.1306868 | I21: =I20*J21 -> 1.1893263 | ... P21: =P20*Q21 -> 1 | Q21: 1
A23: d(age) | B23: =SUM(OFFSET(C13:C17,-C19,0))-SUM(OFFSET(B13:B17,-C19,0)) -> 83297 | C23: =SUM(OFFSET(D13:D17,-D19,0))-SUM(OFFSET(C13:C17,-D19,0)) -> 121948 | D23: =SUM(OFFSET(E13:E17,-E19,0))-SUM(OFFSET(D13:D17,-E19,0)) -> 166311 | E23: =SUM(OFFSET(F13:F17,-F19,0))-SUM(OFFSET(E13:E17,-F19,0)) -> 70041 | F23: =SUM(OFFSET(G13:G17,-G19,0))-SUM(OFFSET(F13:F17,-G19,0)) -> 69780 | G23: =SUM(OFFSET(H13:H17,-H19,0))-SUM(OFFSET(G13:G17,-H19,0)) -> 101546 | H23: =SUM(OFFSET(I13:I17,-I19,0))-SUM(OFFSET(H13:H17,-I19,0)) -> -17546 | I23: =SUM(OFFSET(J13:J17,-J19,0))-SUM(OFFSET(I13:I17,-J19,0)) -> 38926 | ... K23: =SUM(OFFSET(L13:L17,-L19,0))-SUM(OFFSET(K13:K17,-L19,0)) -> 0 | L23: =SUM(M3:M6)-SUM(L3:L6) -> 0 | M23: =SUM(N3:N5)-SUM(M3:M5) -> 0 | N23: =SUM(O3:O4)-SUM(N3:N4) -> 0 | O23: =SUM(P3:P4)-SUM(O3:O4) -> 0 | P23: =SUM(Q3)-SUM(P3) -> 0
A24: n(age) | B24: =SUM(OFFSET(C13:C17,-C19,0)) -> 141664 | C24: =SUM(OFFSET(D13:D17,-D19,0)) -> 257007 | D24: =SUM(OFFSET(E13:E17,-E19,0)) -> 398058 | E24: =SUM(OFFSET(F13:F17,-F19,0)) -> 414057 | F24: =SUM(OFFSET(G13:G17,-G19,0)) -> 464775 | G24: =SUM(OFFSET(H13:H17,-H19,0)) -> 490262 | H24: =SUM(OFFSET(I13:I17,-I19,0)) -> 338322 | I24: =SUM(OFFSET(J13:J17,-J19,0)) -> 255993 | ... K24: =SUM(OFFSET(L13:L17,-L19,0)) -> 0 | L24: =SUM(M3:M6) -> 0 | M24: =SUM(N3:N6) -> 0 | N24: =SUM(O3:O6) -> 0 | O24: =SUM(P3:P6) -> 0 | P24: =SUM(Q3:Q6) -> 0
A25: h(age) | B25: =IF(B24=0,0,B23/B24) -> 0.58798989 | C25: =IF(C24=0,0,C23/C24) -> 0.47449291 | D25: =IF(D24=0,0,D23/D24) -> 0.41780595 | E25: =IF(E24=0,0,E23/E24) -> 0.16915787 | F25: =IF(F24=0,0,F23/F24) -> 0.15013716 | G25: =IF(G24=0,0,G23/G24) -> 0.20712599 | H25: =IF(H24=0,0,H23/H24) -> -0.051861836 | I25: =IF(I24=0,0,I23/I24) -> 0.15205885 | ... P25: =IF(P24=0,0,P23/P24) -> 0
A27: F(age) | B27: =C27*(1-B25) -> 0.062414201 | C27: =D27*(1-C25) -> 0.15148706 | D27: =E27*(1-D25) -> 0.28826835 | E27: =F27*(1-E25) -> 0.49514136 | F27: =G27*(1-F25) -> 0.59595119 | G27: =H27*(1-G25) -> 0.7012322 | H27: =I27*(1-H25) -> 0.88441819 | I27: =J27*(1-I25) -> 0.84081213 | ... P27: =Q27*(1-P25) -> 1 | Q27: 1
A28: age-to-age | B28: =1/B27 -> 16.021995 | C28: =1/C27 -> 6.6012238 | D28: =1/D27 -> 3.4689899 | E28: =1/E27 -> 2.0196253 | F28: =1/F27 -> 1.6779898 | G28: =1/G27 -> 1.4260611 | H28: =1/H27 -> 1.1306868 | I28: =1/I27 -> 1.1893263 | ... Q28: =1/Q27 -> 1
A29: age-to-ultimate | B29: =B28/C28 -> 2.4271249 | C29: =C28/D28 -> 1.9029239 | D29: =D28/E28 -> 1.7176404 | E29: =E28/F28 -> 1.2035981 | F29: =F28/G28 -> 1.1766605 | G29: =G28/H28 -> 1.2612344 | H29: =H28/I28 -> 0.9506952 | I29: =I28/J28 -> 1.1793271 | ... P29: =P28/Q28 -> 1
B30: =B29=B20 -> TRUE | C30: =C29=C20 -> TRUE | D30: =D29=D20 -> TRUE | E30: =E29=E20 -> TRUE | F30: =F29=F20 -> TRUE | G30: =G29=G20 -> TRUE | H30: =H29=H20 -> TRUE | I30: =I29=I20 -> TRUE | ... P30: =P29=P20 -> TRUE
A33: LDF Survival Model
A35: weight | B35: =B24*LN(B2)^1.67/1000 -> 647.7797 | C35: =C24*LN(C2)^1.67/1000 -> 1772.3694 | D35: =D24*LN(D2)^1.67/1000 -> 3354.6218 | E35: =E24*LN(E2)^1.67/1000 -> 3969.7439 | F35: =F24*LN(F2)^1.67/1000 -> 4893.1743 | G35: =G24*LN(G2)^1.67/1000 -> 5551.0375 | H35: =H24*LN(H2)^1.67/1000 -> 4064.0419 | I35: =I24*LN(I2)^1.67/1000 -> 3231.3993 | ... P35: =P24*LN(P2)^1.67/1000 -> 0
A36: inv log(age) | B36: =1/LN(B2) -> 0.4024296 | C36: =1/LN(C2) -> 0.31465798 | D36: =1/LN(D2) -> 0.27905531 | E36: =1/LN(E2) -> 0.25831777 | F36: =1/LN(F2) -> 0.24423934 | G36: =1/LN(G2) -> 0.233827 | H36: =1/LN(H2) -> 0.22569202 | I36: =1/LN(I2) -> 0.21908933 | ... Z36: =1/LN(Z2) -> 0.17532225
A37: spline 1 | B37: =VLOOKUP(B2,splines!$A$2:$C$301,2,FALSE) -> 0.34079528 | C37: =VLOOKUP(C2,splines!$A$2:$C$301,2,FALSE) -> 0.23191252 | D37: =VLOOKUP(D2,splines!$A$2:$C$301,2,FALSE) -> 0.17974198 | E37: =VLOOKUP(E2,splines!$A$2:$C$301,2,FALSE) -> 0.14713286 | F37: =VLOOKUP(F2,splines!$A$2:$C$301,2,FALSE) -> 0.12404424 | G37: =VLOOKUP(G2,splines!$A$2:$C$301,2,FALSE) -> 0.10646707 | H37: =VLOOKUP(H2,splines!$A$2:$C$301,2,FALSE) -> 0.092435247 | I37: =VLOOKUP(I2,splines!$A$2:$C$301,2,FALSE) -> 0.080852201 | ... Z37: =VLOOKUP(Z2,splines!$A$2:$C$301,2,FALSE) -> 0
A38: spline 2 | B38: =VLOOKUP(B2,splines!$A$2:$C$301,3,FALSE) -> -0.1304726 | C38: =VLOOKUP(C2,splines!$A$2:$C$301,3,FALSE) -> -0.1021188 | D38: =VLOOKUP(D2,splines!$A$2:$C$301,3,FALSE) -> -0.08287817 | E38: =VLOOKUP(E2,splines!$A$2:$C$301,3,FALSE) -> -0.06952332 | F38: =VLOOKUP(F2,splines!$A$2:$C$301,3,FALSE) -> -0.05953762 | G38: =VLOOKUP(G2,splines!$A$2:$C$301,3,FALSE) -> -0.0516679 | H38: =VLOOKUP(H2,splines!$A$2:$C$301,3,FALSE) -> -0.04523023 | I38: =VLOOKUP(I2,splines!$A$2:$C$301,3,FALSE) -> -0.03981735 | ... Z38: =VLOOKUP(Z2,splines!$A$2:$C$301,3,FALSE) -> 0
A40: Multiplied by Weights:
A41: h(age) | B41: =B25*B35^0.5 -> 14.965234 | C41: =C25*C35^0.5 -> 19.975923 | D41: =D25*D35^0.5 -> 24.198943 | E41: =E25*E35^0.5 -> 10.657944 | F41: =F25*F35^0.5 -> 10.502279 | G41: =G25*G35^0.5 -> 15.431981 | H41: =H25*H35^0.5 -> -3.3061836 | I41: =I25*I35^0.5 -> 8.6438457 | ... P41: =P25*P35^0.5 -> 0
A42: =A38 -> spline 2 | B42: =B38*B$35^0.5 -> -3.3207255 | C42: =C38*C$35^0.5 -> -4.2991522 | D42: =D38*D$35^0.5 -> -4.8002288 | E42: =E38*E$35^0.5 -> -4.3803796 | F42: =F38*F$35^0.5 -> -4.1647296 | G42: =G38*G$35^0.5 -> -3.8495316 | H42: =H38*H$35^0.5 -> -2.8834198 | I42: =I38*I$35^0.5 -> -2.2634331 | ... P42: =P38*P$35^0.5 -> 0
A43: =A37 -> spline 1 | B43: =B37*B$35^0.5 -> 8.6737567 | C43: =C37*C$35^0.5 -> 9.7634053 | D43: =D37*D$35^0.5 -> 10.410493 | E43: =E37*E$35^0.5 -> 9.2702387 | F43: =F37*F$35^0.5 -> 8.6770469 | G43: =G37*G$35^0.5 -> 7.9323593 | H43: =H37*H$35^0.5 -> 5.892732 | I43: =I37*I$35^0.5 -> 4.5960756 | ... P43: =P37*P$35^0.5 -> 0
A44: inv log(age) | B44: =B36*B$35^0.5 -> 10.242444 | C44: =C36*C$35^0.5 -> 13.246949 | D44: =D36*D$35^0.5 -> 16.162632 | E44: =E36*E$35^0.5 -> 16.275544 | F44: =F36*F$35^0.5 -> 17.084842 | G44: =G36*G$35^0.5 -> 17.421347 | H44: =H36*H$35^0.5 -> 14.38783 | I44: =I36*I$35^0.5 -> 12.45422 | ... P44: =P36*P$35^0.5 -> 0
B47: inv log(age) | C47: spline 1 | D47: spline 2
A48: Parameters | B48: {=LINEST(B41:P41,B42:P44,FALSE)} -> -1.3682924 | C48: 0.45315274 | D48: -7.7405828 | E48: 0
A50: Fitted
...

Sheet Example 2
B1: Age
A2: Year | B2: 12 | C2: 24 | D2: 36 | E2: 48 | F2: 60 | G2: 72 | H2: 84 | I2: 96 | J2: 108 | K2: 120 | L2: 132 | M2: 144 | N2: 156 | O2: 168 | P2: 180 | Q2: 192 | R2: 204 | S2: 216 | T2: 228 | U2: 240 | V2: 252 | W2: 264 | X2: 276 | Y2: 288 | Z2: 300
A3: 2012
A4: 2013 | B4: 387026.81 | C4: 463552.06 | D4: 485844.29 | E4: 778173.73 | F4: 909494.57 | G4: 1026309.7 | H4: 990261.69 | I4: 990261.69 | J4: 1025162.2 | K4: 1025162.2 | L4: 1025162.2 | M4: 1025162.2 | N4: 1025162.2 | O4: 1025162.2
A5: 2014 | B5: 721554.38 | C5: 1017504.5 | D5: 1986074.2 | E5: 2575477.6 | F5: 3477456.1 | G5: 3247546.1 | H5: 3246444.4 | I5: 3246444.4 | J5: 3246444.4 | K5: 3246444.4 | L5: 3246444.4 | M5: 3246444.4 | N5: 3246444.4
A6: 2015 | B6: 3512563.7 | C6: 5266562.4 | D6: 6351170.8 | E6: 7008749.9 | F6: 7839785.9 | G6: 7643692.7 | H6: 7600920.3 | I6: 7601336.4 | J6: 8654880 | K6: 7600713.1 | L6: 7600713.1 | M6: 7600713.1
A7: 2016 | B7: 4870653.2 | C7: 8588861.6 | D7: 14932192 | E7: 17189503 | F7: 17301048 | G7: 17271027 | H7: 17271833 | I7: 17266960 | J7: 17267700 | K7: 17267700 | L7: 17267700
A8: 2017 | B8: 5768068.2 | C8: 10037064 | D8: 10652258 | E8: 12006272 | F8: 12089140 | G8: 12769213 | H8: 14135430 | I8: 14025377 | J8: 14942623 | K8: 14991352
A9: 2018 | B9: 5019038.7 | C9: 7594422.4 | D9: 8270724.6 | E9: 8827020.9 | F9: 9476244.8 | G9: 9398204.9 | H9: 9247393.1 | I9: 9630246.6 | J9: 11231985
A10: 2019 | B10: 4799936.1 | C10: 9923861.3 | D10: 11191566 | E10: 11744990 | F10: 11492857 | G10: 13545433 | H10: 16304933 | I10: 12414661
A11: 2020 | B11: 5493944.8 | C11: 9782585 | D11: 11469779 | E11: 13748604 | F11: 15373592 | G11: 15553060 | H11: 15821035
A12: 2021 | B12: 3957732.8 | C12: 7073422.4 | D12: 9012357.9 | E12: 12220605 | F12: 12527620 | G12: 12890339
A13: 2022 | B13: 4420890.6 | C13: 6193275.4 | D13: 8009139.6 | E13: 8449642.2 | F13: 9497311.3
A14: 2023 | B14: 3503613.8 | C14: 6135103.6 | D14: 6985432.1 | E14: 8658113.4
A15: 2024 | B15: 7754842.6 | C15: 13049523 | D15: 15714107
A16: 2025 | B16: 5291461.8 | C16: 13312434
A17: 2026 | B17: 6373903.7
B19: 0 | C19: 1 | D19: 2 | E19: 3 | F19: 4 | G19: 5 | H19: 6 | I19: 7 | J19: 8 | K19: 9 | L19: 10 | M19: 11 | N19: 12 | O19: 13 | P19: 14 | Q19: 15
A20: age-to-age | B20: =SUM(OFFSET(C13:C17,-B19-1,0))/SUM(OFFSET(B13:B17,-B19-1,0)) -> 1.8357977 | C20: =SUM(OFFSET(D13:D17,-C19-1,0))/SUM(OFFSET(C13:C17,-C19-1,0)) -> 1.2120785 | D20: =SUM(OFFSET(E13:E17,-D19-1,0))/SUM(OFFSET(D13:D17,-D19-1,0)) -> 1.1747157 | E20: =SUM(OFFSET(F13:F17,-E19-1,0))/SUM(OFFSET(E13:E17,-E19-1,0)) -> 1.0614059 | F20: =SUM(OFFSET(G13:G17,-F19-1,0))/SUM(OFFSET(F13:F17,-F19-1,0)) -> 1.0524414 | G20: =SUM(OFFSET(H13:H17,-G19-1,0))/SUM(OFFSET(G13:G17,-G19-1,0)) -> 1.0619182 | H20: =SUM(OFFSET(I13:I17,-H19-1,0))/SUM(OFFSET(H13:H17,-H19-1,0)) -> 0.9438987 | I20: =SUM(OFFSET(J13:J17,-I19-1,0))/SUM(OFFSET(I13:I17,-I19-1,0)) -> 1.0690215 | J20: =SUM(OFFSET(K13:K17,-J19-1,0))/SUM(OFFSET(J13:J17,-J19-1,0)) -> 0.97772466 | K20: =SUM(L3:L7)/SUM(K3:K7) -> 1 | L20: =SUM(M3:M6)/SUM(L3:L6) -> 1 | M20: =SUM(N3:N5)/SUM(M3:M5) -> 1 | N20: =SUM(O3:O4)/SUM(N3:N4) -> 1 | O20: 1 | P20: 1
A21: age-to-ultimate | B21: =B20*C21 -> 3.0590545 | C21: =C20*D21 -> 1.6663353 | D21: =D20*E21 -> 1.3747751 | E21: =E20*F21 -> 1.1703045 | F21: =F20*G21 -> 1.1025985 | G21: =G20*H21 -> 1.0476579 | H21: =H20*I21 -> 0.98657111 | I21: =I20*J21 -> 1.0452087 | ... P21: =P20*Q21 -> 1 | Q21: 1
A23: d(age) | B23: =SUM(OFFSET(C13:C17,-C19,0))-SUM(OFFSET(B13:B17,-C19,0)) -> 20835217 | C23: =SUM(OFFSET(D13:D17,-D19,0))-SUM(OFFSET(C13:C17,-D19,0)) -> 8956905.3 | D23: =SUM(OFFSET(E13:E17,-E19,0))-SUM(OFFSET(D13:D17,-E19,0)) -> 8153680.1 | E23: =SUM(OFFSET(F13:F17,-F19,0))-SUM(OFFSET(E13:E17,-F19,0)) -> 3376762.6 | F23: =SUM(OFFSET(G13:G17,-G19,0))-SUM(OFFSET(F13:F17,-G19,0)) -> 3196796.3 | G23: =SUM(OFFSET(H13:H17,-H19,0))-SUM(OFFSET(G13:G17,-H19,0)) -> 4243687.1 | H23: =SUM(OFFSET(I13:I17,-I19,0))-SUM(OFFSET(H13:H17,-I19,0)) -> -3621928.2 | I23: =SUM(OFFSET(J13:J17,-J19,0))-SUM(OFFSET(I13:I17,-J19,0)) -> 3573267.8 | ... K23: =SUM(OFFSET(L13:L17,-L19,0))-SUM(OFFSET(K13:K17,-L19,0)) -> 0 | L23: =SUM(M3:M6)-SUM(L3:L6) -> 0 | M23: =SUM(N3:N5)-SUM(M3:M5) -> 0 | N23: =SUM(O3:O4)-SUM(N3:N4) -> 0
A24: n(age) | B24: =SUM(OFFSET(C13:C17,-C19,0)) -> 45763758 | C24: =SUM(OFFSET(D13:D17,-D19,0)) -> 51190815 | D24: =SUM(OFFSET(E13:E17,-E19,0)) -> 54821955 | E24: =SUM(OFFSET(F13:F17,-F19,0)) -> 58367625 | F24: =SUM(OFFSET(G13:G17,-G19,0)) -> 64156250 | G24: =SUM(OFFSET(H13:H17,-H19,0)) -> 72780624 | H24: =SUM(OFFSET(I13:I17,-I19,0)) -> 60938581 | I24: =SUM(OFFSET(J13:J17,-J19,0)) -> 55343632 | ... K24: =SUM(OFFSET(L13:L17,-L19,0)) -> 29140019 | L24: =SUM(M3:M6) -> 11872320 | M24: =SUM(N3:N6) -> 4271606.6 | N24: =SUM(O3:O6) -> 1025162.2 | O24: =SUM(P3:P6) -> 0 | P24: =SUM(Q3:Q6) -> 0
A25: h(age) | B25: =IF(B24=0,0,B23/B24) -> 0.45527766 | C25: =IF(C24=0,0,C23/C24) -> 0.17497095 | D25: =IF(D24=0,0,D23/D24) -> 0.1487302 | E25: =IF(E24=0,0,E23/E24) -> 0.05785335 | F25: =IF(F24=0,0,F23/F24) -> 0.049828292 | G25: =IF(G24=0,0,G23/G24) -> 0.058307924 | H25: =IF(H24=0,0,H23/H24) -> -0.059435716 | I25: =IF(I24=0,0,I23/I24) -> 0.064565111 | ... P25: =IF(P24=0,0,P23/P24) -> 0
A27: F(age) | B27: =C27*(1-B25) -> 0.32689839 | C27: =D27*(1-C25) -> 0.6001193 | D27: =E27*(1-D25) -> 0.72739172 | E27: =F27*(1-E25) -> 0.85447847 | F27: =G27*(1-F25) -> 0.90694848 | G27: =H27*(1-G25) -> 0.95451008 | H27: =I27*(1-H25) -> 1.0136117 | I27: =J27*(1-I25) -> 0.95674675 | ... P27: =Q27*(1-P25) -> 1 | Q27: 1
A28: age-to-age | B28: =1/B27 -> 3.0590545 | C28: =1/C27 -> 1.6663353 | D28: =1/D27 -> 1.3747751 | E28: =1/E27 -> 1.1703045 | F28: =1/F27 -> 1.1025985 | G28: =1/G27 -> 1.0476579 | H28: =1/H27 -> 0.98657111 | I28: =1/I27 -> 1.0452087 | ... Q28: =1/Q27 -> 1
A29: age-to-ultimate | B29: =B28/C28 -> 1.8357977 | C29: =C28/D28 -> 1.2120785 | D29: =D28/E28 -> 1.1747157 | E29: =E28/F28 -> 1.0614059 | F29: =F28/G28 -> 1.0524414 | G29: =G28/H28 -> 1.0619182 | H29: =H28/I28 -> 0.9438987 | I29: =I28/J28 -> 1.0690215 | ... P29: =P28/Q28 -> 1
B30: =B29=B20 -> TRUE | C30: =C29=C20 -> TRUE | D30: =D29=D20 -> TRUE | E30: =E29=E20 -> TRUE | F30: =F29=F20 -> TRUE | G30: =G29=G20 -> TRUE | H30: =H29=H20 -> FALSE | I30: =I29=I20 -> TRUE | ... P30: =P29=P20 -> TRUE
A33: LDF Survival Model
A35: weight | B35: =B24*LN(B2)^1.67/1000 -> 209261.59 | C35: =C24*LN(C2)^1.67/1000 -> 353021.64 | D35: =D24*LN(D2)^1.67/1000 -> 462010.37 | E35: =E24*LN(E2)^1.67/1000 -> 559595.71 | F35: =F24*LN(F2)^1.67/1000 -> 675440.19 | G35: =G24*LN(G2)^1.67/1000 -> 824065.45 | H35: =H24*LN(H2)^1.67/1000 -> 732015.5 | I35: =I24*LN(I2)^1.67/1000 -> 698602.61 | ... P35: =P24*LN(P2)^1.67/1000 -> 0
A36: inv log(age) | B36: =1/LN(B2) -> 0.4024296 | C36: =1/LN(C2) -> 0.31465798 | D36: =1/LN(D2) -> 0.27905531 | E36: =1/LN(E2) -> 0.25831777 | F36: =1/LN(F2) -> 0.24423934 | G36: =1/LN(G2) -> 0.233827 | H36: =1/LN(H2) -> 0.22569202 | I36: =1/LN(I2) -> 0.21908933 | ... Z36: =1/LN(Z2) -> 0.17532225
A37: spline 1 | B37: =VLOOKUP(B2,splines!$A$2:$C$301,2,FALSE) -> 0.34079528 | C37: =VLOOKUP(C2,splines!$A$2:$C$301,2,FALSE) -> 0.23191252 | D37: =VLOOKUP(D2,splines!$A$2:$C$301,2,FALSE) -> 0.17974198 | E37: =VLOOKUP(E2,splines!$A$2:$C$301,2,FALSE) -> 0.14713286 | F37: =VLOOKUP(F2,splines!$A$2:$C$301,2,FALSE) -> 0.12404424 | G37: =VLOOKUP(G2,splines!$A$2:$C$301,2,FALSE) -> 0.10646707 | H37: =VLOOKUP(H2,splines!$A$2:$C$301,2,FALSE) -> 0.092435247 | I37: =VLOOKUP(I2,splines!$A$2:$C$301,2,FALSE) -> 0.080852201 | ... Z37: =VLOOKUP(Z2,splines!$A$2:$C$301,2,FALSE) -> 0
A38: spline 2 | B38: =VLOOKUP(B2,splines!$A$2:$C$301,3,FALSE) -> -0.1304726 | C38: =VLOOKUP(C2,splines!$A$2:$C$301,3,FALSE) -> -0.1021188 | D38: =VLOOKUP(D2,splines!$A$2:$C$301,3,FALSE) -> -0.08287817 | E38: =VLOOKUP(E2,splines!$A$2:$C$301,3,FALSE) -> -0.06952332 | F38: =VLOOKUP(F2,splines!$A$2:$C$301,3,FALSE) -> -0.05953762 | G38: =VLOOKUP(G2,splines!$A$2:$C$301,3,FALSE) -> -0.0516679 | H38: =VLOOKUP(H2,splines!$A$2:$C$301,3,FALSE) -> -0.04523023 | I38: =VLOOKUP(I2,splines!$A$2:$C$301,3,FALSE) -> -0.03981735 | ... Z38: =VLOOKUP(Z2,splines!$A$2:$C$301,3,FALSE) -> 0
A40: Multiplied by Weights:
A41: h(age) | B41: =B25*B35^0.5 -> 208.2673 | C41: =C25*C35^0.5 -> 103.96008 | D41: =D25*D35^0.5 -> 101.09392 | E41: =E25*E35^0.5 -> 43.277852 | F41: =F25*F35^0.5 -> 40.951465 | G41: =G25*G35^0.5 -> 52.930797 | H41: =H25*H35^0.5 -> -50.851953 | I41: =I25*I35^0.5 -> 53.965102 | ... P41: =P25*P35^0.5 -> 0
A42: =A38 -> spline 2 | B42: =B38*B$35^0.5 -> -59.684845 | C42: =C38*C$35^0.5 -> -60.674523 | D42: =D38*D$35^0.5 -> -56.333406 | E42: =E38*E$35^0.5 -> -52.007705 | F42: =F38*F$35^0.5 -> -48.931093 | G42: =G38*G$35^0.5 -> -46.903112 | H42: =H38*H$35^0.5 -> -38.698037 | I42: =I38*I$35^0.5 -> -33.280317 | ... P42: =P38*P$35^0.5 -> 0
A43: =A37 -> spline 1 | B43: =B37*B$35^0.5 -> 155.8972 | C43: =C37*C$35^0.5 -> 137.79227 | D43: =D37*D$35^0.5 -> 122.17304 | E43: =E37*E$35^0.5 -> 110.0644 | F43: =F37*F$35^0.5 -> 101.94597 | G43: =G37*G$35^0.5 -> 96.64873 | H43: =H37*H$35^0.5 -> 79.08566 | I43: =I37*I$35^0.5 -> 67.578251 | ... P43: =P37*P$35^0.5 -> 0
A44: inv log(age) | B44: =B36*B$35^0.5 -> 184.0919 | C44: =C36*C$35^0.5 -> 186.956 | D44: =D36*D$35^0.5 -> 189.67765 | E44: =E36*E$35^0.5 -> 193.23752 | F44: =F36*F$35^0.5 -> 200.72851 | G44: =G36*G$35^0.5 -> 212.26359 | H44: =H36*H$35^0.5 -> 193.09736 | I44: =I36*I$35^0.5 -> 183.12023 | ... P44: =P36*P$35^0.5 -> 0
B47: inv log(age) | C47: spline 1 | D47: spline 2
A48: Parameters | B48: {=LINEST(B41:P41,B42:P44,FALSE)} -> -0.26057402 | C48: 4.5355609 | D48: 7.5765056 | E48: 0
A50: Fitted
...

Sheet splines
A1: age
A2: 1
A3: 2 | B3: 0.23964318 | C3: 0.8790336
A4: 3 | B4: 0.52399692 | C4: 0.1374424
A5: 4 | B5: 0.53143537 | C5: -0.03529708
A6: 5 | B6: 0.50257968 | C6: -0.09504912
A7: 6 | B7: 0.47063694 | C7: -0.1195746
A8: 7 | B8: 0.44145471 | C8: -0.1301067
A9: 8 | B9: 0.41580566 | C9: -0.1342285
A10: 9 | B10: 0.39338405 | C10: -0.135142
A11: 10 | B11: 0.37370091 | C11: -0.134362
A12: 11 | B12: 0.35629886 | C12: -0.1326648
A13: 12 | B13: 0.34079528 | C13: -0.1304726
A14: 13 | B14: 0.3268804 | C14: -0.1280247
... A301: 300 | B301: 0 | C301: 0
